<?xml version="1.0" ?>
<robot name="localbot" xmlns:xacro="http://ros.org/wiki/xacro">
  <xacro:include filename="$(find localbot_description)/urdf/common_properties.xacro"/>

  <xacro:property name="name" value="$(arg name)"/>
  <xacro:property name="color" value="$(arg color)"/>


  <!-- Include other files-->
  <xacro:include filename="$(find localbot_description)/urdf/properties.xacro"/>
  <xacro:include filename="$(find localbot_description)/urdf/VLP-16.urdf.xacro"/>
  <xacro:include filename="$(find localbot_description)/urdf/astra.urdf.xacro" />

  <xacro:include filename="$(find velodyne_description)/urdf/VLP-16.urdf.xacro"/>


  <xacro:include filename="$(find localbot_description)/urdf/localbot.gazebo.macro.xacro"/>

  <link name="base_footprint"/>

  <joint name="base_joint" type="fixed">
    <parent link="base_footprint"/>
    <child link="base_link" />
    <origin xyz="0 0 0.010" rpy="0 0 0"/>
  </joint>

  <link name="base_link">
    <visual>
      <origin xyz="-0.064 0 0.0" rpy="0 0 0"/>
      <geometry>
        <mesh filename="package://turtlebot3_description/meshes/bases/waffle_pi_base.stl" scale="0.001 0.001 0.001"/>
      </geometry>
      <material name="Grey"/>
    </visual>

    <collision>
      <origin xyz="-0.064 0 0.047" rpy="0 0 0.5"/>
      <geometry>
        <box size="0.266 0.266 0.094"/>
      </geometry>
    </collision>

    <inertial>
      <origin xyz="0 0 0" rpy="0 0 0"/>
      <mass value="1.3729096e+00"/>
      <inertia ixx="8.7002718e-03" ixy="-4.7576583e-05" ixz="1.1160499e-04"
               iyy="8.6195418e-03" iyz="-3.5422299e-06"
               izz="1.4612727e-02" />
    </inertial>
  </link>

  <joint name="wheel_left_joint" type="continuous">
    <parent link="base_link"/>
    <child link="wheel_left_link"/>
    <origin xyz="0.0 0.144 0.023" rpy="-1.57 0 0"/>
    <axis xyz="0 0 1"/>
  </joint>

  <link name="wheel_left_link">
    <visual>
      <origin xyz="0 0 0" rpy="1.57 0 0"/>
      <geometry>
        <mesh filename="package://turtlebot3_description/meshes/wheels/left_tire.stl" scale="0.001 0.001 0.001"/>
      </geometry>
      <material name="Grey"/>
    </visual>

    <collision>
      <origin xyz="0 0 0" rpy="0 0 0"/>
      <geometry>
        <cylinder length="0.018" radius="0.033"/>
      </geometry>
    </collision>

    <inertial>
      <origin xyz="0 0 0" />
      <mass value="2.8498940e-02" />
      <inertia ixx="1.1175580e-05" ixy="-4.2369783e-11" ixz="-5.9381719e-09"
               iyy="1.1192413e-05" iyz="-1.4400107e-11"
               izz="2.0712558e-05" />
      </inertial>
  </link>

  <joint name="wheel_right_joint" type="continuous">
    <parent link="base_link"/>
    <child link="wheel_right_link"/>
    <origin xyz="0.0 -0.144 0.023" rpy="-1.57 0 0"/>
    <axis xyz="0 0 1"/>
  </joint>

  <link name="wheel_right_link">
    <visual>
      <origin xyz="0 0 0" rpy="1.57 0 0"/>
      <geometry>
        <mesh filename="package://turtlebot3_description/meshes/wheels/right_tire.stl" scale="0.001 0.001 0.001"/>
      </geometry>
<!--      <material name="Grey"/>-->
      <material name="Grey"/>
    </visual>

    <collision>
      <origin xyz="0 0 0" rpy="0 0 0"/>
      <geometry>
        <cylinder length="0.018" radius="0.033"/>
      </geometry>
    </collision>

    <inertial>
      <origin xyz="0 0 0" />
      <mass value="2.8498940e-02" />
      <inertia ixx="1.1175580e-05" ixy="-4.2369783e-11" ixz="-5.9381719e-09"
               iyy="1.1192413e-05" iyz="-1.4400107e-11"
               izz="2.0712558e-05" />
      </inertial>
  </link>

  <joint name="caster_back_right_joint" type="fixed">
    <parent link="base_link"/>
    <child link="caster_back_right_link"/>
    <origin xyz="-0.177 -0.064 -0.004" rpy="-1.57 0 0"/>
  </joint>

  <link name="caster_back_right_link">
    <collision>
      <origin xyz="0 0.001 0" rpy="0 0 0"/>
      <geometry>
        <box size="0.030 0.009 0.020"/>
      </geometry>
    </collision>

    <inertial>
      <origin xyz="0 0 0" />
      <mass value="0.005" />
      <inertia ixx="0.001" ixy="0.0" ixz="0.0"
               iyy="0.001" iyz="0.0"
               izz="0.001" />
    </inertial>
  </link>

  <joint name="caster_back_left_joint" type="fixed">
    <parent link="base_link"/>
    <child link="caster_back_left_link"/>
    <origin xyz="-0.177 0.064 -0.004" rpy="-1.57 0 0"/>
  </joint>

  <link name="caster_back_left_link">
    <collision>
      <origin xyz="0 0.001 0" rpy="0 0 0"/>
      <geometry>
        <box size="0.030 0.009 0.020"/>
      </geometry>
    </collision>

    <inertial>
      <origin xyz="0 0 0" />
      <mass value="0.005" />
      <inertia ixx="0.001" ixy="0.0" ixz="0.0"
               iyy="0.001" iyz="0.0"
               izz="0.001" />
    </inertial>
  </link>

  <joint name="imu_joint" type="fixed">
    <parent link="base_link"/>
    <child link="imu_link"/>
    <origin xyz="0.0 0 0.068" rpy="0 0 0"/>
  </joint>

  <link name="imu_link"/>

  </robot> 

  <!-- <link name="camera_support_link">
  </link>

  <joint name="platform_support_camera_link" type="fixed">
    <origin xyz="0.02 0 1.5" rpy="0.01 -0.35 0.2"/>
    <parent link="base_link"/>
    <child link="camera_support_link"/>
  </joint>

  <xacro:sensor_astra prefix="camera" parent="camera_support_link">
    <origin xyz="0.02 0.07 0.015" rpy="0 0.0 0" />
  </xacro:sensor_astra>


    3d lidar
  <xacro:VLP-16 name="lidar3d" parent="base_link" topic="/lidar3d/points">
        <origin xyz="0 0 0.7" rpy="0 0 0" />
  </xacro:VLP-16> -->

